# 异常

https://www.zhihu.com/answer/909161116 这篇文章十分值得一读。相关主题的文章可参考[其他可选方式 (njuics.github.io)](https://njuics.github.io/OnJava8/#/book/15-Exceptions?id=其他可选方式)

异常的意义请参阅[异常概念 (njuics.github.io)](https://njuics.github.io/OnJava8/#/book/15-Exceptions?id=异常概念)

在理论上，异常处理有两种基本模型：

- 终止模型（它是 Java 和 C++所支持的模型）在这种模型中，将假设错误非常严重，以至于程序无法返回到异常发生的地方继续执行。一旦异常被抛出，就表明错误已无法挽回，也不能回来继续执行。
- 恢复模型：意思是异常处理程序的工作是修正错误，然后重新尝试调用出问题的方法，并认为第二次能成功。对于恢复模型，通常希望异常被处理之后能继续执行程序。如果想要用 Java 实现类似恢复的行为，那么在遇见错误时就不能抛出异常，而是调用方法来修正该错误。或者，把 try 块放在 while 循环里，这样就不断地进入 try 块，直到得到满意的结果。虽然恢复模型开始显得很吸引人，但不是很实用。其中的主要原因可能是它所导致的耦合：恢复性的处理程序需要了解异常抛出的地点，这势必要包含依赖于抛出位置的非通用性代码。这增加了代码编写和维护的困难，对于异常可能会从许多地方抛出的大型程序来说，更是如此。





### 异常的处理逻辑

如果要自己定义异常类，则必须从已有的异常类继承！



捕获异常的顺序：从上到下依次考察相应地catch块，如果抛出的异常类型可以转换成catch中的异常类型，则进入该catch块进行处理异常。一定要注意catch块的顺序，保证具体的异常类型放置前面。此外，Java7引入了多重捕获机制，他是解决异常处理逻辑相同的问题：

~~~java
public class SameHandler {
    void x() throws Except1, Except2, Except3, Except4 {}
    void process() {}
    void f() {
        try {
            x();
        } catch(Except1 e) {
            process();
        } catch(Except2 e) {
            process();
        } catch(Except3 e) {
            process();
        } catch(Except4 e) {
            process();
        }
    }
}

//多重捕获
public class MultiCatch {
    void x() throws Except1, Except2, Except3, Except4 {}
    void process() {}
    void f() {
        try {
            x();
        } catch(Except1 | Except2 | Except3 | Except4 e) {
            process();
        }
    }
}
~~~

这对书写更整洁的代码很有帮助。



从非try块或者catch块中抛出异常，则将该异常转交给上一级环境（嵌套的try块或者上一级方法）。如果一个异常在程序中得不到任何处理，则由操作系统处理该异常，一般处理方法是终止此程序并提示用户。在try块中抛出的异常一定要从catch中或者同方法中嵌套的try块内得到处理！



异常声明的完整含义是我忽略此异常或者部分处理该异常，剩下的转交给你处理。

异常声明在方法后使用了附加的关键字 throws，后面接一个所有潜在异常类型的列表，所以方法定义可能看起来像这样：

~~~java
void f() throws TooBig, TooSmall, DivZero { //....
~~~

此时如果调用f()，必须放置在try块内，还得有相应的catch块进行处理，这是编译器强制要求的！在调用f()的方法中同样throws f()的异常类型，则可以无需处理从f()中抛出的异常，事实上这样做可以在不知道怎么处理该异常时十分有用，~~一种偷懒的好方法 :)~~。

但是，要是这样写：

~~~java
void f() { // ...
~~~

就表示此方法保证异常在f()会catch掉，不会抛出任何异常。





### 异常链

常常会想要在捕获一个异常后抛出另一个异常，并且希望把原始异常的信息保存下来，这被称为异常链。

相关的异常方法：在 Throwable 的子类中，只有三种基本的异常类提供了带 cause 参数（Throwable的子类）的构造器。它们是 Error（用于 Java 虚拟机报告系统错误）、Exception 以及 RuntimeException。如果要把其他类型的异常链接起来，应该使用 initCause() 方法而不是构造器。

~~~java
class A {
    void f() throws Exception {
        throw new Exception();
    }
    void g() {
        try {
        	f();
        } catch(Exception e) {
            Exception e1 = new Exception(e);
            Exception e2 = new Exception(e);
            e2.initCause(e);
		}
    }
}
~~~



### 异常中的资源管理

为了在无论何种情况下都能够清理对象所持有的资源，于是就引入finally块，无论try中异常是否被抛出，finally 子句总能被执行。甚至在try或catch块中执行return语句前，也要执行finally块。

Java在设计finally时有个严重的缺陷，那就是异常缺失！下面来看个例子

~~~java
// exceptions/LostMessage.java
// How an exception can be lost
class VeryImportantException extends Exception {
    @Override
    public String toString() {
        return "A very important exception!";
    }
}
class HoHumException extends Exception {
    @Override
    public String toString() {
        return "A trivial exception";
    }
}
public class LostMessage {
    void f() throws VeryImportantException {
        throw new VeryImportantException();
    }
    void dispose() throws HoHumException {
        throw new HoHumException();
    }
    public static void main(String[] args) {
        try {
            LostMessage lm = new LostMessage();
            try {
                lm.f();
            } finally {
                lm.dispose();
                //return 			//更简单的丢失情况
            }
        } catch(VeryImportantException | HoHumException e) {
            System.out.println(e);
        }
    }
}

/* Output：
	A trivial exception
*/
~~~

很明显，VeryImportantException缺失了。C++把这种“前一个异常还没处理就抛出下一个异常”的情形看成是糟糕的编程错误！此时需要嵌套try块进行处理，对于运行时异常直接抛出，不做处理！



在构造器内出现异常时，要小心谨慎，下面通过一个例子说明在构造器内常用的异常手法：

~~~java
// exceptions/InputFile.java
// Paying attention to exceptions in constructors
import java.io.*;
public class InputFile {
    private BufferedReader in;
    public InputFile(String fname) throws Exception {
        try {
            in = new BufferedReader(new FileReader(fname));
            // Other code that might throw exceptions
        } catch(FileNotFoundException e) {
            System.out.println("Could not open " + fname);
            // Wasn't open, so don't close it
            throw e;
        } catch(Exception e) {
            // All other exceptions must close it
            try {
                in.close();
            } catch(IOException e2) {
                System.out.println("in.close() unsuccessful");
            }
            throw e; // 异常被重新抛出，对于构造器而言这么做是很合适的，因为你总不希望去误导调用方，让他认为“这个对象已经创建完毕，可以使用了
        } finally {
        //finally会每次都执行清理代码。如果构造器在其执行过程中半途而废，也许该对象的某些部分还没有被成功创建，而这些部分在finally子句中却是要被清理的，这会引发致命错误
        }
    }
    public String getLine() {
        String s;
        try {
            s = in.readLine();
        } catch(IOException e) {
            throw new RuntimeException("readLine() failed");
            //在设计异常时有一个问题：应该把异常全部放在这一层处理；还是先处理一部分，然后再向上层抛出相同的（或新的）异常；又或者是不做任何处理直接向上层抛出
        }
        return s;
    }
    public void dispose() {
        try {
            in.close();
            System.out.println("dispose() successful");
        } catch(IOException e2) {
            throw new RuntimeException("in.close() failed");
        }
        //可能你会考虑把上述功能放到 finalize() 里面，但是你不知道 finalize() 会不会被调用（即使能确定它将被调用，也不知道在什么时候调用），这也是 Java 的缺陷：除了内存的清理之外，所有的清理都不会自动发生。所以必须告诉客户端程序员，这是他们的责任。
    }
    
    public static void main(String[] args) {
        // [0]:
        try {
            InputFile in = new InputFile("Cleanup.java");
            //对于在构造阶段可能会抛出异常，并且要求清理的类，最安全的使用方式是使用嵌套的 try 子句：
            try {
                String s;
                int i = 1;
                while((s = in.getLine()) != null)
                    ; // Perform line-by-line processing here...
            } catch(Exception e) {
                System.out.println("Caught Exception in main");
                e.printStackTrace(System.out);
            } finally {
                in.dispose();
                //如果构造成功，我们肯定想确保对象能够被清理，因此在构造之后立即创建了一个新的 try 语句块。执行清理的 finally 与内部的 try 语句块相关联。在这种方式中，finally 子句在构造失败时是不会执行的，而在构造成功时将总是执行。
            }
        } catch(Exception e) {
            System.out.println(
                    "InputFile construction failed");
           	//请仔细观察这里的逻辑：对 InputFile 对象的构造在其自己的 try 语句块中有效，如果构造失败，将进入外部的 catch 子句，而 dispose() 方法不会被调用。这是一种通用的清理手法，值得学习。
        }
        // [1]:
        NeedsCleanup nc1 = new NeedsCleanup();
        try {
        // ...
        } finally {
            nc1.dispose();
        }
        
        
        // [2]:
        // If construction cannot fail,
        // you can group objects:
        NeedsCleanup nc2 = new NeedsCleanup();
        NeedsCleanup nc3 = new NeedsCleanup();
        try {
        // ...
        } finally {
            nc3.dispose(); // Reverse order of construction，防止依赖关系对清理工作的影响。
            
            //[3]:
            try {
            	nc2.dispose();
            } catch(Exception e) {
                
            }
        }
    }
}

~~~

上述清理惯用法在构造器不抛出任何异常时也应该运用，其基本规则是：在创建需要清理的对象之后，若接下来的代码会产生异常，则立即进入一个 try-finally 语句块。finally块中清理资源。这种方法仅对必须要调用dispose的对象且接下来代码会产生异常的情景下适用，否则代码会混乱不堪。总而言之，若代码会产生异常，则必须把对象的清理工作（如果有的话）放在下一级的try-finally块中，这样对象总能得到清理。注意，如果 dispose() 可以抛出异常，那么你可能需要额外的 try 语句块。



来看一段“糟糕”的代码：

~~~java
package exceptions;
import java.io.*;
public class MessyExceptions {
    public static void main(String[] args) {
        try {
            InputStream in = new FileInputStream(new File("MessyExceptions.java"));
            try {
                int contents = in.read();
            } catch (IOException e) {
                // Handle the error 
            } finally {
                try {
                    in.close();
                } catch (IOException e) {
                    // Handle the error
                }
            }
        } catch(Exception e) {
            // Handle the error
        }
    }
}
~~~

不幸的是，若按照标准的异常处理代码要求就不得不这么写。

不过，好在设计者们意识到这一点，在java7中做出了改进，引入了 try-with-resources 语法：

~~~java
import java.io.*;
public class TryWithResources {
    public static void main(String[] args) {
        try(InputStream in = new FileInputStream(new File("TryWithResources.java"))) {
            int contents = in.read();
            // Process contents
        } catch(IOException e) {
            // Handle the error
        }
    }
}
~~~

括号内的部分称为资源规范头（resource specification header）。资源规范头中可以包含多个定义，并且通过分号进行分割（最后一个分号是可选的）。更重要的是，无论你何时退出 try 块（正常或通过异常），和以前的 finally 子句等价的代码都会被执行，并且不用编写那些杂乱而棘手的代码。如果有多个对象，则逆序清理它们。这是一项重要的改进。它的实现原理如下： try-with-resources 定义子句中创建的对象（在括号内）必须实现 `java.lang.AutoCloseable` 接口，这个接口只有一个方法：`close()`。

如果在构造对象时产生异常，则在同一try-catch块中进行处理，并合理、安全地调用已构造出对象的close方法，不像之前那样嵌套try块。

~~~java
class A {
    public static void main(String[] args) {
        try (
            B b = new B();
            C c = new C();
            B d = new B();
        ) {
            throw new Exception();
        } catch (MyException e) {
            
		} catch (Exception e) {
            
        }
    }
}
class MyException extends Exception { }
class B implements AutoCloseable{
    B() {}
    @Override
    public void close() {
        System.out.println("Closing B");
	}
}
class C {
    C() throws MyException { throw new MyException(); }
    @Override
    public void close() {
        System.out.println("Closing C");
	}
}


/ * Output
   	Closing B
* /
~~~



如果在调用close时出现异常，则则在同一try-catch块中进行处理，并且会接着逆序调用完所有对象的close()方法。

### 异常与面向对象

当覆盖方法的时候，只能抛出在基类方法的异常说明里列出的那些异常（可以向上转型），这称为异常限制。构造器是静态函数，故不遵循异常限制规则。如果实现多个接口时，有同名方法，但它们所抛出的异常不同，则取它们所抛出异常类型的∩交集。

### Java标准异常

在Java异常系统中，Throwable对象可以分成以下两类

- Error，表示编译时和系统错误（除特殊情况外，一般不用你关心）
- Exception 是可以被抛出的基本异常类型。

Java会自动抛出运行时异常RuntimeException，并无视异常声明的规则。NullPointerExceptio就是一种RuntimeException。RuntimeException 代表的是编程错误，设计程序时一般不做考虑。



- getMessage()
- printStackTrace()，递归也照常适用，打印首次抛出异常的地方到main方法的调用路径。这个方法不考虑重新抛出的情况
- fillInStackTrace()，用于弥补printStackTrace、getStackTrace的缺陷，在重新抛出同一个异常时，printStackTrace并不会更新调用栈信息，此时要显式调用fillInStackTrace()把重新该处设置为首次抛出异常的地方。推荐用异常链而不是这种方法。
- getLocalizedMessage()
- getStackTrace()，printStackTrace() 方法所提供的信息可以通过 getStackTrace() 方法来直接访问。这个方法将返回一个由栈轨迹中的元素所构成的数组，其中每一个元素都表示栈中的一桢。元素 0 是栈顶元素，并且是调用序列中的最后一个方法调用（这个 Throwable 被创建和抛出之处）







在这里我要谈谈如何面对不知怎么处理异常的情况，最常见的情况就是将它"吞掉":

~~~java
try {
    //code block
} catch (Exception e) { //empty code block}
~~~

或者throws掉

~~~java
void f() throws Exception {
    try {
        
    } finally {
        
    }
}
~~~



但是推荐的方式是 RuntimeException + 异常链

